[2024-02-11T00:15:03.276+0000] {taskinstance.py:1956} INFO - Dependencies all met for dep_context=non-requeueable deps ti=<TaskInstance: first_dag_v3.third_task scheduled__2024-02-10T00:00:00+00:00 [queued]>
[2024-02-11T00:15:03.300+0000] {taskinstance.py:1956} INFO - Dependencies all met for dep_context=requeueable deps ti=<TaskInstance: first_dag_v3.third_task scheduled__2024-02-10T00:00:00+00:00 [queued]>
[2024-02-11T00:15:03.314+0000] {taskinstance.py:2170} INFO - Starting attempt 1 of 6
[2024-02-11T00:15:03.347+0000] {taskinstance.py:2191} INFO - Executing <Task(BashOperator): third_task> on 2024-02-10 00:00:00+00:00
[2024-02-11T00:15:03.354+0000] {standard_task_runner.py:60} INFO - Started process 1011 to run task
[2024-02-11T00:15:03.360+0000] {standard_task_runner.py:87} INFO - Running: ['***', 'tasks', 'run', 'first_dag_v3', 'third_task', 'scheduled__2024-02-10T00:00:00+00:00', '--job-id', '42', '--raw', '--subdir', 'DAGS_FOLDER/first_dag.py', '--cfg-path', '/tmp/tmpvjng71jy']
[2024-02-11T00:15:03.363+0000] {standard_task_runner.py:88} INFO - Job 42: Subtask third_task
[2024-02-11T00:15:03.578+0000] {task_command.py:423} INFO - Running <TaskInstance: first_dag_v3.third_task scheduled__2024-02-10T00:00:00+00:00 [running]> on host 5c55586955c6
[2024-02-11T00:15:03.825+0000] {taskinstance.py:2480} INFO - Exporting env vars: AIRFLOW_CTX_DAG_OWNER='Nathan' AIRFLOW_CTX_DAG_ID='first_dag_v3' AIRFLOW_CTX_TASK_ID='third_task' AIRFLOW_CTX_EXECUTION_DATE='2024-02-10T00:00:00+00:00' AIRFLOW_CTX_TRY_NUMBER='1' AIRFLOW_CTX_DAG_RUN_ID='scheduled__2024-02-10T00:00:00+00:00'
[2024-02-11T00:15:03.829+0000] {subprocess.py:63} INFO - Tmp dir root location: /tmp
[2024-02-11T00:15:03.848+0000] {subprocess.py:75} INFO - Running command: ['/usr/bin/bash', '-c', 'This is the third taks']
[2024-02-11T00:15:03.887+0000] {subprocess.py:86} INFO - Output:
[2024-02-11T00:15:03.896+0000] {subprocess.py:93} INFO - /usr/bin/bash: line 1: This: command not found
[2024-02-11T00:15:03.897+0000] {subprocess.py:97} INFO - Command exited with return code 127
[2024-02-11T00:15:03.916+0000] {taskinstance.py:2698} ERROR - Task failed with exception
Traceback (most recent call last):
  File "/home/airflow/.local/lib/python3.8/site-packages/airflow/models/taskinstance.py", line 433, in _execute_task
    result = execute_callable(context=context, **execute_callable_kwargs)
  File "/home/airflow/.local/lib/python3.8/site-packages/airflow/operators/bash.py", line 212, in execute
    raise AirflowException(
airflow.exceptions.AirflowException: Bash command failed. The command returned a non-zero exit code 127.
[2024-02-11T00:15:03.922+0000] {taskinstance.py:1138} INFO - Marking task as UP_FOR_RETRY. dag_id=first_dag_v3, task_id=third_task, execution_date=20240210T000000, start_date=20240211T001503, end_date=20240211T001503
[2024-02-11T00:15:03.941+0000] {standard_task_runner.py:107} ERROR - Failed to execute job 42 for task third_task (Bash command failed. The command returned a non-zero exit code 127.; 1011)
[2024-02-11T00:15:03.984+0000] {local_task_job_runner.py:234} INFO - Task exited with return code 1
[2024-02-11T00:15:04.042+0000] {taskinstance.py:3280} INFO - 0 downstream tasks scheduled from follow-on schedule check
