[2024-02-11T00:15:03.389+0000] {taskinstance.py:1956} INFO - Dependencies all met for dep_context=non-requeueable deps ti=<TaskInstance: first_dag_v3.second_task scheduled__2024-02-10T00:00:00+00:00 [queued]>
[2024-02-11T00:15:03.437+0000] {taskinstance.py:1956} INFO - Dependencies all met for dep_context=requeueable deps ti=<TaskInstance: first_dag_v3.second_task scheduled__2024-02-10T00:00:00+00:00 [queued]>
[2024-02-11T00:15:03.459+0000] {taskinstance.py:2170} INFO - Starting attempt 1 of 6
[2024-02-11T00:15:03.483+0000] {taskinstance.py:2191} INFO - Executing <Task(BashOperator): second_task> on 2024-02-10 00:00:00+00:00
[2024-02-11T00:15:03.503+0000] {standard_task_runner.py:60} INFO - Started process 1012 to run task
[2024-02-11T00:15:03.508+0000] {standard_task_runner.py:87} INFO - Running: ['***', 'tasks', 'run', 'first_dag_v3', 'second_task', 'scheduled__2024-02-10T00:00:00+00:00', '--job-id', '47', '--raw', '--subdir', 'DAGS_FOLDER/first_dag.py', '--cfg-path', '/tmp/tmpsgavl48e']
[2024-02-11T00:15:03.517+0000] {standard_task_runner.py:88} INFO - Job 47: Subtask second_task
[2024-02-11T00:15:03.692+0000] {task_command.py:423} INFO - Running <TaskInstance: first_dag_v3.second_task scheduled__2024-02-10T00:00:00+00:00 [running]> on host 5c55586955c6
[2024-02-11T00:15:03.988+0000] {taskinstance.py:2480} INFO - Exporting env vars: AIRFLOW_CTX_DAG_OWNER='Nathan' AIRFLOW_CTX_DAG_ID='first_dag_v3' AIRFLOW_CTX_TASK_ID='second_task' AIRFLOW_CTX_EXECUTION_DATE='2024-02-10T00:00:00+00:00' AIRFLOW_CTX_TRY_NUMBER='1' AIRFLOW_CTX_DAG_RUN_ID='scheduled__2024-02-10T00:00:00+00:00'
[2024-02-11T00:15:03.993+0000] {subprocess.py:63} INFO - Tmp dir root location: /tmp
[2024-02-11T00:15:03.994+0000] {subprocess.py:75} INFO - Running command: ['/usr/bin/bash', '-c', 'This is the second task']
[2024-02-11T00:15:04.032+0000] {subprocess.py:86} INFO - Output:
[2024-02-11T00:15:04.034+0000] {subprocess.py:93} INFO - /usr/bin/bash: line 1: This: command not found
[2024-02-11T00:15:04.035+0000] {subprocess.py:97} INFO - Command exited with return code 127
[2024-02-11T00:15:04.056+0000] {taskinstance.py:2698} ERROR - Task failed with exception
Traceback (most recent call last):
  File "/home/airflow/.local/lib/python3.8/site-packages/airflow/models/taskinstance.py", line 433, in _execute_task
    result = execute_callable(context=context, **execute_callable_kwargs)
  File "/home/airflow/.local/lib/python3.8/site-packages/airflow/operators/bash.py", line 212, in execute
    raise AirflowException(
airflow.exceptions.AirflowException: Bash command failed. The command returned a non-zero exit code 127.
[2024-02-11T00:15:04.061+0000] {taskinstance.py:1138} INFO - Marking task as UP_FOR_RETRY. dag_id=first_dag_v3, task_id=second_task, execution_date=20240210T000000, start_date=20240211T001503, end_date=20240211T001504
[2024-02-11T00:15:04.090+0000] {standard_task_runner.py:107} ERROR - Failed to execute job 47 for task second_task (Bash command failed. The command returned a non-zero exit code 127.; 1012)
[2024-02-11T00:15:04.142+0000] {local_task_job_runner.py:234} INFO - Task exited with return code 1
[2024-02-11T00:15:04.331+0000] {taskinstance.py:3280} INFO - 0 downstream tasks scheduled from follow-on schedule check
