[2024-02-11T00:15:01.364+0000] {taskinstance.py:1956} INFO - Dependencies all met for dep_context=non-requeueable deps ti=<TaskInstance: first_dag_v3.third_task scheduled__2024-02-07T00:00:00+00:00 [queued]>
[2024-02-11T00:15:01.475+0000] {taskinstance.py:1956} INFO - Dependencies all met for dep_context=requeueable deps ti=<TaskInstance: first_dag_v3.third_task scheduled__2024-02-07T00:00:00+00:00 [queued]>
[2024-02-11T00:15:01.477+0000] {taskinstance.py:2170} INFO - Starting attempt 1 of 6
[2024-02-11T00:15:01.621+0000] {taskinstance.py:2191} INFO - Executing <Task(BashOperator): third_task> on 2024-02-07 00:00:00+00:00
[2024-02-11T00:15:01.670+0000] {standard_task_runner.py:60} INFO - Started process 988 to run task
[2024-02-11T00:15:01.661+0000] {standard_task_runner.py:87} INFO - Running: ['***', 'tasks', 'run', 'first_dag_v3', 'third_task', 'scheduled__2024-02-07T00:00:00+00:00', '--job-id', '40', '--raw', '--subdir', 'DAGS_FOLDER/first_dag.py', '--cfg-path', '/tmp/tmp2noy5c58']
[2024-02-11T00:15:01.685+0000] {standard_task_runner.py:88} INFO - Job 40: Subtask third_task
[2024-02-11T00:15:02.109+0000] {task_command.py:423} INFO - Running <TaskInstance: first_dag_v3.third_task scheduled__2024-02-07T00:00:00+00:00 [running]> on host 5c55586955c6
[2024-02-11T00:15:02.704+0000] {taskinstance.py:2480} INFO - Exporting env vars: AIRFLOW_CTX_DAG_OWNER='Nathan' AIRFLOW_CTX_DAG_ID='first_dag_v3' AIRFLOW_CTX_TASK_ID='third_task' AIRFLOW_CTX_EXECUTION_DATE='2024-02-07T00:00:00+00:00' AIRFLOW_CTX_TRY_NUMBER='1' AIRFLOW_CTX_DAG_RUN_ID='scheduled__2024-02-07T00:00:00+00:00'
[2024-02-11T00:15:02.708+0000] {subprocess.py:63} INFO - Tmp dir root location: /tmp
[2024-02-11T00:15:02.710+0000] {subprocess.py:75} INFO - Running command: ['/usr/bin/bash', '-c', 'This is the third taks']
[2024-02-11T00:15:02.755+0000] {subprocess.py:86} INFO - Output:
[2024-02-11T00:15:02.774+0000] {subprocess.py:93} INFO - /usr/bin/bash: line 1: This: command not found
[2024-02-11T00:15:02.778+0000] {subprocess.py:97} INFO - Command exited with return code 127
[2024-02-11T00:15:02.944+0000] {taskinstance.py:2698} ERROR - Task failed with exception
Traceback (most recent call last):
  File "/home/airflow/.local/lib/python3.8/site-packages/airflow/models/taskinstance.py", line 433, in _execute_task
    result = execute_callable(context=context, **execute_callable_kwargs)
  File "/home/airflow/.local/lib/python3.8/site-packages/airflow/operators/bash.py", line 212, in execute
    raise AirflowException(
airflow.exceptions.AirflowException: Bash command failed. The command returned a non-zero exit code 127.
[2024-02-11T00:15:02.952+0000] {taskinstance.py:1138} INFO - Marking task as UP_FOR_RETRY. dag_id=first_dag_v3, task_id=third_task, execution_date=20240207T000000, start_date=20240211T001501, end_date=20240211T001502
[2024-02-11T00:15:03.039+0000] {standard_task_runner.py:107} ERROR - Failed to execute job 40 for task third_task (Bash command failed. The command returned a non-zero exit code 127.; 988)
[2024-02-11T00:15:03.056+0000] {local_task_job_runner.py:234} INFO - Task exited with return code 1
[2024-02-11T00:15:03.106+0000] {taskinstance.py:3280} INFO - 0 downstream tasks scheduled from follow-on schedule check
