[2024-02-11T00:15:03.405+0000] {taskinstance.py:1956} INFO - Dependencies all met for dep_context=non-requeueable deps ti=<TaskInstance: first_dag_v3.third_task scheduled__2024-02-09T00:00:00+00:00 [queued]>
[2024-02-11T00:15:03.423+0000] {taskinstance.py:1956} INFO - Dependencies all met for dep_context=requeueable deps ti=<TaskInstance: first_dag_v3.third_task scheduled__2024-02-09T00:00:00+00:00 [queued]>
[2024-02-11T00:15:03.424+0000] {taskinstance.py:2170} INFO - Starting attempt 1 of 6
[2024-02-11T00:15:03.506+0000] {taskinstance.py:2191} INFO - Executing <Task(BashOperator): third_task> on 2024-02-09 00:00:00+00:00
[2024-02-11T00:15:03.522+0000] {standard_task_runner.py:60} INFO - Started process 1013 to run task
[2024-02-11T00:15:03.530+0000] {standard_task_runner.py:87} INFO - Running: ['***', 'tasks', 'run', 'first_dag_v3', 'third_task', 'scheduled__2024-02-09T00:00:00+00:00', '--job-id', '46', '--raw', '--subdir', 'DAGS_FOLDER/first_dag.py', '--cfg-path', '/tmp/tmpjrvdhvj3']
[2024-02-11T00:15:03.535+0000] {standard_task_runner.py:88} INFO - Job 46: Subtask third_task
[2024-02-11T00:15:03.708+0000] {task_command.py:423} INFO - Running <TaskInstance: first_dag_v3.third_task scheduled__2024-02-09T00:00:00+00:00 [running]> on host 5c55586955c6
[2024-02-11T00:15:03.908+0000] {taskinstance.py:2480} INFO - Exporting env vars: AIRFLOW_CTX_DAG_OWNER='Nathan' AIRFLOW_CTX_DAG_ID='first_dag_v3' AIRFLOW_CTX_TASK_ID='third_task' AIRFLOW_CTX_EXECUTION_DATE='2024-02-09T00:00:00+00:00' AIRFLOW_CTX_TRY_NUMBER='1' AIRFLOW_CTX_DAG_RUN_ID='scheduled__2024-02-09T00:00:00+00:00'
[2024-02-11T00:15:03.913+0000] {subprocess.py:63} INFO - Tmp dir root location: /tmp
[2024-02-11T00:15:03.914+0000] {subprocess.py:75} INFO - Running command: ['/usr/bin/bash', '-c', 'This is the third taks']
[2024-02-11T00:15:03.927+0000] {subprocess.py:86} INFO - Output:
[2024-02-11T00:15:03.932+0000] {subprocess.py:93} INFO - /usr/bin/bash: line 1: This: command not found
[2024-02-11T00:15:03.933+0000] {subprocess.py:97} INFO - Command exited with return code 127
[2024-02-11T00:15:03.949+0000] {taskinstance.py:2698} ERROR - Task failed with exception
Traceback (most recent call last):
  File "/home/airflow/.local/lib/python3.8/site-packages/airflow/models/taskinstance.py", line 433, in _execute_task
    result = execute_callable(context=context, **execute_callable_kwargs)
  File "/home/airflow/.local/lib/python3.8/site-packages/airflow/operators/bash.py", line 212, in execute
    raise AirflowException(
airflow.exceptions.AirflowException: Bash command failed. The command returned a non-zero exit code 127.
[2024-02-11T00:15:03.961+0000] {taskinstance.py:1138} INFO - Marking task as UP_FOR_RETRY. dag_id=first_dag_v3, task_id=third_task, execution_date=20240209T000000, start_date=20240211T001503, end_date=20240211T001503
[2024-02-11T00:15:03.986+0000] {standard_task_runner.py:107} ERROR - Failed to execute job 46 for task third_task (Bash command failed. The command returned a non-zero exit code 127.; 1013)
[2024-02-11T00:15:04.028+0000] {local_task_job_runner.py:234} INFO - Task exited with return code 1
[2024-02-11T00:15:04.056+0000] {taskinstance.py:3280} INFO - 0 downstream tasks scheduled from follow-on schedule check
